{
 "cells": [
  {
   "cell_type": "markdown",
   "id": "2ba34bef",
   "metadata": {
    "colab_type": "text",
    "id": "view-in-github"
   },
   "source": [
    "<a href=\"https://colab.research.google.com/github/HannaPylieva-GBI/classification/blob/main/lightgbm_classification.ipynb\" target=\"_parent\"><img src=\"https://colab.research.google.com/assets/colab-badge.svg\" alt=\"Open In Colab\"/></a>"
   ]
  },
  {
   "cell_type": "code",
   "execution_count": 18,
   "id": "JD6wW942wWc4",
   "metadata": {
    "colab": {
     "base_uri": "https://localhost:8080/"
    },
    "collapsed": true,
    "id": "JD6wW942wWc4",
    "jupyter": {
     "outputs_hidden": true
    },
    "outputId": "6d2a1ad4-0e90-4fb0-c9a1-373fbffdc08a",
    "tags": []
   },
   "outputs": [
    {
     "name": "stdout",
     "output_type": "stream",
     "text": [
      "Looking in indexes: https://pypi.org/simple, https://us-python.pkg.dev/colab-wheels/public/simple/\n",
      "Collecting tensorflow_text\n",
      "  Downloading tensorflow_text-2.11.0-cp39-cp39-manylinux_2_17_x86_64.manylinux2014_x86_64.whl (5.8 MB)\n",
      "\u001b[2K     \u001b[90m━━━━━━━━━━━━━━━━━━━━━━━━━━━━━━━━━━━━━━━━\u001b[0m \u001b[32m5.8/5.8 MB\u001b[0m \u001b[31m88.2 MB/s\u001b[0m eta \u001b[36m0:00:00\u001b[0m\n",
      "\u001b[?25hRequirement already satisfied: tensorflow<2.12,>=2.11.0 in /usr/local/lib/python3.9/dist-packages (from tensorflow_text) (2.11.0)\n",
      "Requirement already satisfied: tensorflow-hub>=0.8.0 in /usr/local/lib/python3.9/dist-packages (from tensorflow_text) (0.13.0)\n",
      "Requirement already satisfied: typing-extensions>=3.6.6 in /usr/local/lib/python3.9/dist-packages (from tensorflow<2.12,>=2.11.0->tensorflow_text) (4.5.0)\n",
      "Requirement already satisfied: absl-py>=1.0.0 in /usr/local/lib/python3.9/dist-packages (from tensorflow<2.12,>=2.11.0->tensorflow_text) (1.4.0)\n",
      "Requirement already satisfied: grpcio<2.0,>=1.24.3 in /usr/local/lib/python3.9/dist-packages (from tensorflow<2.12,>=2.11.0->tensorflow_text) (1.51.3)\n",
      "Requirement already satisfied: astunparse>=1.6.0 in /usr/local/lib/python3.9/dist-packages (from tensorflow<2.12,>=2.11.0->tensorflow_text) (1.6.3)\n",
      "Requirement already satisfied: numpy>=1.20 in /usr/local/lib/python3.9/dist-packages (from tensorflow<2.12,>=2.11.0->tensorflow_text) (1.22.4)\n",
      "Requirement already satisfied: opt-einsum>=2.3.2 in /usr/local/lib/python3.9/dist-packages (from tensorflow<2.12,>=2.11.0->tensorflow_text) (3.3.0)\n",
      "Requirement already satisfied: libclang>=13.0.0 in /usr/local/lib/python3.9/dist-packages (from tensorflow<2.12,>=2.11.0->tensorflow_text) (15.0.6.1)\n",
      "Requirement already satisfied: setuptools in /usr/local/lib/python3.9/dist-packages (from tensorflow<2.12,>=2.11.0->tensorflow_text) (63.4.3)\n",
      "Requirement already satisfied: flatbuffers>=2.0 in /usr/local/lib/python3.9/dist-packages (from tensorflow<2.12,>=2.11.0->tensorflow_text) (23.3.3)\n",
      "Requirement already satisfied: termcolor>=1.1.0 in /usr/local/lib/python3.9/dist-packages (from tensorflow<2.12,>=2.11.0->tensorflow_text) (2.2.0)\n",
      "Requirement already satisfied: tensorboard<2.12,>=2.11 in /usr/local/lib/python3.9/dist-packages (from tensorflow<2.12,>=2.11.0->tensorflow_text) (2.11.2)\n",
      "Requirement already satisfied: tensorflow-io-gcs-filesystem>=0.23.1 in /usr/local/lib/python3.9/dist-packages (from tensorflow<2.12,>=2.11.0->tensorflow_text) (0.31.0)\n",
      "Requirement already satisfied: wrapt>=1.11.0 in /usr/local/lib/python3.9/dist-packages (from tensorflow<2.12,>=2.11.0->tensorflow_text) (1.15.0)\n",
      "Requirement already satisfied: keras<2.12,>=2.11.0 in /usr/local/lib/python3.9/dist-packages (from tensorflow<2.12,>=2.11.0->tensorflow_text) (2.11.0)\n",
      "Requirement already satisfied: h5py>=2.9.0 in /usr/local/lib/python3.9/dist-packages (from tensorflow<2.12,>=2.11.0->tensorflow_text) (3.8.0)\n",
      "Requirement already satisfied: tensorflow-estimator<2.12,>=2.11.0 in /usr/local/lib/python3.9/dist-packages (from tensorflow<2.12,>=2.11.0->tensorflow_text) (2.11.0)\n",
      "Requirement already satisfied: protobuf<3.20,>=3.9.2 in /usr/local/lib/python3.9/dist-packages (from tensorflow<2.12,>=2.11.0->tensorflow_text) (3.19.6)\n",
      "Requirement already satisfied: google-pasta>=0.1.1 in /usr/local/lib/python3.9/dist-packages (from tensorflow<2.12,>=2.11.0->tensorflow_text) (0.2.0)\n",
      "Requirement already satisfied: packaging in /usr/local/lib/python3.9/dist-packages (from tensorflow<2.12,>=2.11.0->tensorflow_text) (23.0)\n",
      "Requirement already satisfied: six>=1.12.0 in /usr/local/lib/python3.9/dist-packages (from tensorflow<2.12,>=2.11.0->tensorflow_text) (1.15.0)\n",
      "Requirement already satisfied: gast<=0.4.0,>=0.2.1 in /usr/local/lib/python3.9/dist-packages (from tensorflow<2.12,>=2.11.0->tensorflow_text) (0.4.0)\n",
      "Requirement already satisfied: wheel<1.0,>=0.23.0 in /usr/local/lib/python3.9/dist-packages (from astunparse>=1.6.0->tensorflow<2.12,>=2.11.0->tensorflow_text) (0.40.0)\n",
      "Requirement already satisfied: google-auth<3,>=1.6.3 in /usr/local/lib/python3.9/dist-packages (from tensorboard<2.12,>=2.11->tensorflow<2.12,>=2.11.0->tensorflow_text) (2.16.2)\n",
      "Requirement already satisfied: tensorboard-data-server<0.7.0,>=0.6.0 in /usr/local/lib/python3.9/dist-packages (from tensorboard<2.12,>=2.11->tensorflow<2.12,>=2.11.0->tensorflow_text) (0.6.1)\n",
      "Requirement already satisfied: google-auth-oauthlib<0.5,>=0.4.1 in /usr/local/lib/python3.9/dist-packages (from tensorboard<2.12,>=2.11->tensorflow<2.12,>=2.11.0->tensorflow_text) (0.4.6)\n",
      "Requirement already satisfied: tensorboard-plugin-wit>=1.6.0 in /usr/local/lib/python3.9/dist-packages (from tensorboard<2.12,>=2.11->tensorflow<2.12,>=2.11.0->tensorflow_text) (1.8.1)\n",
      "Requirement already satisfied: werkzeug>=1.0.1 in /usr/local/lib/python3.9/dist-packages (from tensorboard<2.12,>=2.11->tensorflow<2.12,>=2.11.0->tensorflow_text) (2.2.3)\n",
      "Requirement already satisfied: markdown>=2.6.8 in /usr/local/lib/python3.9/dist-packages (from tensorboard<2.12,>=2.11->tensorflow<2.12,>=2.11.0->tensorflow_text) (3.4.1)\n",
      "Requirement already satisfied: requests<3,>=2.21.0 in /usr/local/lib/python3.9/dist-packages (from tensorboard<2.12,>=2.11->tensorflow<2.12,>=2.11.0->tensorflow_text) (2.27.1)\n",
      "Requirement already satisfied: cachetools<6.0,>=2.0.0 in /usr/local/lib/python3.9/dist-packages (from google-auth<3,>=1.6.3->tensorboard<2.12,>=2.11->tensorflow<2.12,>=2.11.0->tensorflow_text) (5.3.0)\n",
      "Requirement already satisfied: rsa<5,>=3.1.4 in /usr/local/lib/python3.9/dist-packages (from google-auth<3,>=1.6.3->tensorboard<2.12,>=2.11->tensorflow<2.12,>=2.11.0->tensorflow_text) (4.9)\n",
      "Requirement already satisfied: pyasn1-modules>=0.2.1 in /usr/local/lib/python3.9/dist-packages (from google-auth<3,>=1.6.3->tensorboard<2.12,>=2.11->tensorflow<2.12,>=2.11.0->tensorflow_text) (0.2.8)\n",
      "Requirement already satisfied: requests-oauthlib>=0.7.0 in /usr/local/lib/python3.9/dist-packages (from google-auth-oauthlib<0.5,>=0.4.1->tensorboard<2.12,>=2.11->tensorflow<2.12,>=2.11.0->tensorflow_text) (1.3.1)\n",
      "Requirement already satisfied: importlib-metadata>=4.4 in /usr/local/lib/python3.9/dist-packages (from markdown>=2.6.8->tensorboard<2.12,>=2.11->tensorflow<2.12,>=2.11.0->tensorflow_text) (6.0.0)\n",
      "Requirement already satisfied: certifi>=2017.4.17 in /usr/local/lib/python3.9/dist-packages (from requests<3,>=2.21.0->tensorboard<2.12,>=2.11->tensorflow<2.12,>=2.11.0->tensorflow_text) (2022.12.7)\n",
      "Requirement already satisfied: urllib3<1.27,>=1.21.1 in /usr/local/lib/python3.9/dist-packages (from requests<3,>=2.21.0->tensorboard<2.12,>=2.11->tensorflow<2.12,>=2.11.0->tensorflow_text) (1.26.15)\n",
      "Requirement already satisfied: idna<4,>=2.5 in /usr/local/lib/python3.9/dist-packages (from requests<3,>=2.21.0->tensorboard<2.12,>=2.11->tensorflow<2.12,>=2.11.0->tensorflow_text) (3.4)\n",
      "Requirement already satisfied: charset-normalizer~=2.0.0 in /usr/local/lib/python3.9/dist-packages (from requests<3,>=2.21.0->tensorboard<2.12,>=2.11->tensorflow<2.12,>=2.11.0->tensorflow_text) (2.0.12)\n",
      "Requirement already satisfied: MarkupSafe>=2.1.1 in /usr/local/lib/python3.9/dist-packages (from werkzeug>=1.0.1->tensorboard<2.12,>=2.11->tensorflow<2.12,>=2.11.0->tensorflow_text) (2.1.2)\n",
      "Requirement already satisfied: zipp>=0.5 in /usr/local/lib/python3.9/dist-packages (from importlib-metadata>=4.4->markdown>=2.6.8->tensorboard<2.12,>=2.11->tensorflow<2.12,>=2.11.0->tensorflow_text) (3.15.0)\n",
      "Requirement already satisfied: pyasn1<0.5.0,>=0.4.6 in /usr/local/lib/python3.9/dist-packages (from pyasn1-modules>=0.2.1->google-auth<3,>=1.6.3->tensorboard<2.12,>=2.11->tensorflow<2.12,>=2.11.0->tensorflow_text) (0.4.8)\n",
      "Requirement already satisfied: oauthlib>=3.0.0 in /usr/local/lib/python3.9/dist-packages (from requests-oauthlib>=0.7.0->google-auth-oauthlib<0.5,>=0.4.1->tensorboard<2.12,>=2.11->tensorflow<2.12,>=2.11.0->tensorflow_text) (3.2.2)\n",
      "Installing collected packages: tensorflow_text\n",
      "Successfully installed tensorflow_text-2.11.0\n"
     ]
    }
   ],
   "source": [
    "!pip install tensorflow_text"
   ]
  },
  {
   "cell_type": "code",
   "execution_count": null,
   "id": "a3fa6072-660d-4773-af6e-5d8ced894002",
   "metadata": {
    "id": "a3fa6072-660d-4773-af6e-5d8ced894002"
   },
   "outputs": [
    {
     "name": "stderr",
     "output_type": "stream",
     "text": [
      "ERROR:root:Internal Python error in the inspect module.\n",
      "Below is the traceback from this internal error.\n",
      "\n",
      "ERROR:root:Internal Python error in the inspect module.\n",
      "Below is the traceback from this internal error.\n",
      "\n",
      "ERROR:root:Internal Python error in the inspect module.\n",
      "Below is the traceback from this internal error.\n",
      "\n"
     ]
    },
    {
     "name": "stdout",
     "output_type": "stream",
     "text": [
      "ERROR! Session/line number was not unique in database. History logging moved to new session 282\n",
      "Traceback (most recent call last):\n",
      "  File \"/opt/conda/lib/python3.7/site-packages/IPython/core/interactiveshell.py\", line 3552, in run_code\n",
      "    exec(code_obj, self.user_global_ns, self.user_ns)\n",
      "  File \"/tmp/ipykernel_24234/3964101490.py\", line 9, in <module>\n",
      "    import tensorflow_hub as hub\n",
      "  File \"/opt/conda/lib/python3.7/site-packages/tensorflow_hub/__init__.py\", line 29, in <module>\n",
      "    from tensorflow_hub.estimator import LatestModuleExporter\n",
      "  File \"/opt/conda/lib/python3.7/site-packages/tensorflow_hub/estimator.py\", line 63, in <module>\n",
      "    class LatestModuleExporter(tf_v1.estimator.Exporter):\n",
      "AttributeError: module 'tensorflow_hub.tf_v1' has no attribute 'estimator'\n",
      "\n",
      "During handling of the above exception, another exception occurred:\n",
      "\n",
      "Traceback (most recent call last):\n",
      "  File \"/opt/conda/lib/python3.7/site-packages/IPython/core/interactiveshell.py\", line 2098, in showtraceback\n",
      "    stb = value._render_traceback_()\n",
      "AttributeError: 'AttributeError' object has no attribute '_render_traceback_'\n",
      "\n",
      "During handling of the above exception, another exception occurred:\n",
      "\n",
      "Traceback (most recent call last):\n",
      "  File \"/opt/conda/lib/python3.7/site-packages/IPython/core/ultratb.py\", line 1101, in get_records\n",
      "    return _fixed_getinnerframes(etb, number_of_lines_of_context, tb_offset)\n",
      "  File \"/opt/conda/lib/python3.7/site-packages/IPython/core/ultratb.py\", line 248, in wrapped\n",
      "    return f(*args, **kwargs)\n",
      "  File \"/opt/conda/lib/python3.7/site-packages/IPython/core/ultratb.py\", line 281, in _fixed_getinnerframes\n",
      "    records = fix_frame_records_filenames(inspect.getinnerframes(etb, context))\n",
      "  File \"/opt/conda/lib/python3.7/inspect.py\", line 1502, in getinnerframes\n",
      "    frameinfo = (tb.tb_frame,) + getframeinfo(tb, context)\n",
      "  File \"/opt/conda/lib/python3.7/inspect.py\", line 1460, in getframeinfo\n",
      "    filename = getsourcefile(frame) or getfile(frame)\n",
      "  File \"/opt/conda/lib/python3.7/inspect.py\", line 696, in getsourcefile\n",
      "    if getattr(getmodule(object, filename), '__loader__', None) is not None:\n",
      "  File \"/opt/conda/lib/python3.7/inspect.py\", line 733, in getmodule\n",
      "    if ismodule(module) and hasattr(module, '__file__'):\n",
      "  File \"/opt/conda/lib/python3.7/site-packages/tensorflow/__init__.py\", line 50, in __getattr__\n",
      "    module = self._load()\n",
      "  File \"/opt/conda/lib/python3.7/site-packages/tensorflow/__init__.py\", line 44, in _load\n",
      "    module = _importlib.import_module(self.__name__)\n",
      "  File \"/opt/conda/lib/python3.7/importlib/__init__.py\", line 127, in import_module\n",
      "    return _bootstrap._gcd_import(name[level:], package, level)\n",
      "  File \"<frozen importlib._bootstrap>\", line 1006, in _gcd_import\n",
      "  File \"<frozen importlib._bootstrap>\", line 983, in _find_and_load\n",
      "  File \"<frozen importlib._bootstrap>\", line 965, in _find_and_load_unlocked\n",
      "ModuleNotFoundError: No module named 'tensorflow_core.estimator'\n",
      "Traceback (most recent call last):\n",
      "  File \"/opt/conda/lib/python3.7/site-packages/IPython/core/interactiveshell.py\", line 3552, in run_code\n",
      "    exec(code_obj, self.user_global_ns, self.user_ns)\n",
      "  File \"/tmp/ipykernel_24234/3964101490.py\", line 9, in <module>\n",
      "    import tensorflow_hub as hub\n",
      "  File \"/opt/conda/lib/python3.7/site-packages/tensorflow_hub/__init__.py\", line 29, in <module>\n",
      "    from tensorflow_hub.estimator import LatestModuleExporter\n",
      "  File \"/opt/conda/lib/python3.7/site-packages/tensorflow_hub/estimator.py\", line 63, in <module>\n",
      "    class LatestModuleExporter(tf_v1.estimator.Exporter):\n",
      "AttributeError: module 'tensorflow_hub.tf_v1' has no attribute 'estimator'\n",
      "\n",
      "During handling of the above exception, another exception occurred:\n",
      "\n",
      "Traceback (most recent call last):\n",
      "  File \"/opt/conda/lib/python3.7/site-packages/IPython/core/interactiveshell.py\", line 2098, in showtraceback\n",
      "    stb = value._render_traceback_()\n",
      "AttributeError: 'AttributeError' object has no attribute '_render_traceback_'\n",
      "\n",
      "During handling of the above exception, another exception occurred:\n",
      "\n",
      "Traceback (most recent call last):\n",
      "  File \"/opt/conda/lib/python3.7/site-packages/IPython/core/interactiveshell.py\", line 3472, in run_ast_nodes\n",
      "    if (await self.run_code(code, result,  async_=asy)):\n",
      "  File \"/opt/conda/lib/python3.7/site-packages/IPython/core/interactiveshell.py\", line 3569, in run_code\n",
      "    self.showtraceback(running_compiled_code=True)\n",
      "  File \"/opt/conda/lib/python3.7/site-packages/IPython/core/interactiveshell.py\", line 2101, in showtraceback\n",
      "    value, tb, tb_offset=tb_offset)\n",
      "  File \"/opt/conda/lib/python3.7/site-packages/IPython/core/ultratb.py\", line 1368, in structured_traceback\n",
      "    self, etype, value, tb, tb_offset, number_of_lines_of_context)\n",
      "  File \"/opt/conda/lib/python3.7/site-packages/IPython/core/ultratb.py\", line 1268, in structured_traceback\n",
      "    self, etype, value, tb, tb_offset, number_of_lines_of_context\n",
      "  File \"/opt/conda/lib/python3.7/site-packages/IPython/core/ultratb.py\", line 1125, in structured_traceback\n",
      "    tb_offset)\n",
      "  File \"/opt/conda/lib/python3.7/site-packages/IPython/core/ultratb.py\", line 1082, in format_exception_as_a_whole\n",
      "    last_unique, recursion_repeat = find_recursion(orig_etype, evalue, records)\n",
      "  File \"/opt/conda/lib/python3.7/site-packages/IPython/core/ultratb.py\", line 382, in find_recursion\n",
      "    return len(records), 0\n",
      "TypeError: object of type 'NoneType' has no len()\n",
      "\n",
      "During handling of the above exception, another exception occurred:\n",
      "\n",
      "Traceback (most recent call last):\n",
      "  File \"/opt/conda/lib/python3.7/site-packages/IPython/core/interactiveshell.py\", line 2098, in showtraceback\n",
      "    stb = value._render_traceback_()\n",
      "AttributeError: 'TypeError' object has no attribute '_render_traceback_'\n",
      "\n",
      "During handling of the above exception, another exception occurred:\n",
      "\n",
      "Traceback (most recent call last):\n",
      "  File \"/opt/conda/lib/python3.7/site-packages/IPython/core/ultratb.py\", line 1101, in get_records\n",
      "    return _fixed_getinnerframes(etb, number_of_lines_of_context, tb_offset)\n",
      "  File \"/opt/conda/lib/python3.7/site-packages/IPython/core/ultratb.py\", line 248, in wrapped\n",
      "    return f(*args, **kwargs)\n",
      "  File \"/opt/conda/lib/python3.7/site-packages/IPython/core/ultratb.py\", line 281, in _fixed_getinnerframes\n",
      "    records = fix_frame_records_filenames(inspect.getinnerframes(etb, context))\n",
      "  File \"/opt/conda/lib/python3.7/inspect.py\", line 1502, in getinnerframes\n",
      "    frameinfo = (tb.tb_frame,) + getframeinfo(tb, context)\n",
      "  File \"/opt/conda/lib/python3.7/inspect.py\", line 1460, in getframeinfo\n",
      "    filename = getsourcefile(frame) or getfile(frame)\n",
      "  File \"/opt/conda/lib/python3.7/inspect.py\", line 696, in getsourcefile\n",
      "    if getattr(getmodule(object, filename), '__loader__', None) is not None:\n",
      "  File \"/opt/conda/lib/python3.7/inspect.py\", line 733, in getmodule\n",
      "    if ismodule(module) and hasattr(module, '__file__'):\n",
      "  File \"/opt/conda/lib/python3.7/site-packages/tensorflow/__init__.py\", line 50, in __getattr__\n",
      "    module = self._load()\n",
      "  File \"/opt/conda/lib/python3.7/site-packages/tensorflow/__init__.py\", line 44, in _load\n",
      "    module = _importlib.import_module(self.__name__)\n",
      "  File \"/opt/conda/lib/python3.7/importlib/__init__.py\", line 127, in import_module\n",
      "    return _bootstrap._gcd_import(name[level:], package, level)\n",
      "  File \"<frozen importlib._bootstrap>\", line 1006, in _gcd_import\n",
      "  File \"<frozen importlib._bootstrap>\", line 983, in _find_and_load\n",
      "  File \"<frozen importlib._bootstrap>\", line 965, in _find_and_load_unlocked\n",
      "ModuleNotFoundError: No module named 'tensorflow_core.estimator'\n",
      "Traceback (most recent call last):\n",
      "  File \"/opt/conda/lib/python3.7/site-packages/IPython/core/interactiveshell.py\", line 3552, in run_code\n",
      "    exec(code_obj, self.user_global_ns, self.user_ns)\n",
      "  File \"/tmp/ipykernel_24234/3964101490.py\", line 9, in <module>\n",
      "    import tensorflow_hub as hub\n",
      "  File \"/opt/conda/lib/python3.7/site-packages/tensorflow_hub/__init__.py\", line 29, in <module>\n",
      "    from tensorflow_hub.estimator import LatestModuleExporter\n",
      "  File \"/opt/conda/lib/python3.7/site-packages/tensorflow_hub/estimator.py\", line 63, in <module>\n",
      "    class LatestModuleExporter(tf_v1.estimator.Exporter):\n",
      "AttributeError: module 'tensorflow_hub.tf_v1' has no attribute 'estimator'\n",
      "\n",
      "During handling of the above exception, another exception occurred:\n",
      "\n",
      "Traceback (most recent call last):\n",
      "  File \"/opt/conda/lib/python3.7/site-packages/IPython/core/interactiveshell.py\", line 2098, in showtraceback\n",
      "    stb = value._render_traceback_()\n",
      "AttributeError: 'AttributeError' object has no attribute '_render_traceback_'\n",
      "\n",
      "During handling of the above exception, another exception occurred:\n",
      "\n",
      "Traceback (most recent call last):\n",
      "  File \"/opt/conda/lib/python3.7/site-packages/IPython/core/interactiveshell.py\", line 3472, in run_ast_nodes\n",
      "    if (await self.run_code(code, result,  async_=asy)):\n",
      "  File \"/opt/conda/lib/python3.7/site-packages/IPython/core/interactiveshell.py\", line 3569, in run_code\n",
      "    self.showtraceback(running_compiled_code=True)\n",
      "  File \"/opt/conda/lib/python3.7/site-packages/IPython/core/interactiveshell.py\", line 2101, in showtraceback\n",
      "    value, tb, tb_offset=tb_offset)\n",
      "  File \"/opt/conda/lib/python3.7/site-packages/IPython/core/ultratb.py\", line 1368, in structured_traceback\n",
      "    self, etype, value, tb, tb_offset, number_of_lines_of_context)\n",
      "  File \"/opt/conda/lib/python3.7/site-packages/IPython/core/ultratb.py\", line 1268, in structured_traceback\n",
      "    self, etype, value, tb, tb_offset, number_of_lines_of_context\n",
      "  File \"/opt/conda/lib/python3.7/site-packages/IPython/core/ultratb.py\", line 1125, in structured_traceback\n",
      "    tb_offset)\n",
      "  File \"/opt/conda/lib/python3.7/site-packages/IPython/core/ultratb.py\", line 1082, in format_exception_as_a_whole\n",
      "    last_unique, recursion_repeat = find_recursion(orig_etype, evalue, records)\n",
      "  File \"/opt/conda/lib/python3.7/site-packages/IPython/core/ultratb.py\", line 382, in find_recursion\n",
      "    return len(records), 0\n",
      "TypeError: object of type 'NoneType' has no len()\n",
      "\n",
      "During handling of the above exception, another exception occurred:\n",
      "\n",
      "Traceback (most recent call last):\n",
      "  File \"/opt/conda/lib/python3.7/site-packages/IPython/core/interactiveshell.py\", line 2098, in showtraceback\n",
      "    stb = value._render_traceback_()\n",
      "AttributeError: 'TypeError' object has no attribute '_render_traceback_'\n",
      "\n",
      "During handling of the above exception, another exception occurred:\n",
      "\n",
      "Traceback (most recent call last):\n",
      "  File \"/opt/conda/lib/python3.7/site-packages/IPython/core/interactiveshell.py\", line 3029, in _run_cell\n",
      "    return runner(coro)\n",
      "  File \"/opt/conda/lib/python3.7/site-packages/IPython/core/async_helpers.py\", line 78, in _pseudo_sync_runner\n",
      "    coro.send(None)\n",
      "  File \"/opt/conda/lib/python3.7/site-packages/IPython/core/interactiveshell.py\", line 3257, in run_cell_async\n",
      "    interactivity=interactivity, compiler=compiler, result=result)\n",
      "  File \"/opt/conda/lib/python3.7/site-packages/IPython/core/interactiveshell.py\", line 3491, in run_ast_nodes\n",
      "    self.showtraceback()\n",
      "  File \"/opt/conda/lib/python3.7/site-packages/IPython/core/interactiveshell.py\", line 2101, in showtraceback\n",
      "    value, tb, tb_offset=tb_offset)\n",
      "  File \"/opt/conda/lib/python3.7/site-packages/IPython/core/ultratb.py\", line 1368, in structured_traceback\n",
      "    self, etype, value, tb, tb_offset, number_of_lines_of_context)\n",
      "  File \"/opt/conda/lib/python3.7/site-packages/IPython/core/ultratb.py\", line 1268, in structured_traceback\n",
      "    self, etype, value, tb, tb_offset, number_of_lines_of_context\n",
      "  File \"/opt/conda/lib/python3.7/site-packages/IPython/core/ultratb.py\", line 1143, in structured_traceback\n",
      "    chained_exceptions_tb_offset)\n",
      "  File \"/opt/conda/lib/python3.7/site-packages/IPython/core/ultratb.py\", line 1082, in format_exception_as_a_whole\n",
      "    last_unique, recursion_repeat = find_recursion(orig_etype, evalue, records)\n",
      "  File \"/opt/conda/lib/python3.7/site-packages/IPython/core/ultratb.py\", line 382, in find_recursion\n",
      "    return len(records), 0\n",
      "TypeError: object of type 'NoneType' has no len()\n",
      "\n",
      "During handling of the above exception, another exception occurred:\n",
      "\n",
      "Traceback (most recent call last):\n",
      "  File \"/opt/conda/lib/python3.7/site-packages/IPython/core/interactiveshell.py\", line 2098, in showtraceback\n",
      "    stb = value._render_traceback_()\n",
      "AttributeError: 'TypeError' object has no attribute '_render_traceback_'\n",
      "\n",
      "During handling of the above exception, another exception occurred:\n",
      "\n",
      "Traceback (most recent call last):\n",
      "  File \"/opt/conda/lib/python3.7/site-packages/IPython/core/ultratb.py\", line 1101, in get_records\n",
      "    return _fixed_getinnerframes(etb, number_of_lines_of_context, tb_offset)\n",
      "  File \"/opt/conda/lib/python3.7/site-packages/IPython/core/ultratb.py\", line 248, in wrapped\n",
      "    return f(*args, **kwargs)\n",
      "  File \"/opt/conda/lib/python3.7/site-packages/IPython/core/ultratb.py\", line 281, in _fixed_getinnerframes\n",
      "    records = fix_frame_records_filenames(inspect.getinnerframes(etb, context))\n",
      "  File \"/opt/conda/lib/python3.7/inspect.py\", line 1502, in getinnerframes\n",
      "    frameinfo = (tb.tb_frame,) + getframeinfo(tb, context)\n",
      "  File \"/opt/conda/lib/python3.7/inspect.py\", line 1460, in getframeinfo\n",
      "    filename = getsourcefile(frame) or getfile(frame)\n",
      "  File \"/opt/conda/lib/python3.7/inspect.py\", line 696, in getsourcefile\n",
      "    if getattr(getmodule(object, filename), '__loader__', None) is not None:\n",
      "  File \"/opt/conda/lib/python3.7/inspect.py\", line 733, in getmodule\n",
      "    if ismodule(module) and hasattr(module, '__file__'):\n",
      "  File \"/opt/conda/lib/python3.7/site-packages/tensorflow/__init__.py\", line 50, in __getattr__\n",
      "    module = self._load()\n",
      "  File \"/opt/conda/lib/python3.7/site-packages/tensorflow/__init__.py\", line 44, in _load\n",
      "    module = _importlib.import_module(self.__name__)\n",
      "  File \"/opt/conda/lib/python3.7/importlib/__init__.py\", line 127, in import_module\n",
      "    return _bootstrap._gcd_import(name[level:], package, level)\n",
      "  File \"<frozen importlib._bootstrap>\", line 1006, in _gcd_import\n",
      "  File \"<frozen importlib._bootstrap>\", line 983, in _find_and_load\n",
      "  File \"<frozen importlib._bootstrap>\", line 965, in _find_and_load_unlocked\n",
      "ModuleNotFoundError: No module named 'tensorflow_core.estimator'\n"
     ]
    }
   ],
   "source": [
    "import pandas as pd\n",
    "import numpy as np\n",
    "import re\n",
    "\n",
    "from sklearn.metrics import confusion_matrix, accuracy_score, precision_score, recall_score\n",
    "from sklearn.model_selection import train_test_split\n",
    "\n",
    "import tensorflow as tf\n",
    "import tensorflow_hub as hub\n",
    "import tensorflow_text\n",
    "import lightgbm as lgbm\n",
    "\n",
    "from tensorflow.keras.optimizers import Adam, SGD\n",
    "from tensorflow.keras.layers import Dense, Input, BatchNormalization, Dropout, Concatenate\n",
    "from tensorflow.keras.models import Model, Sequential\n",
    "from tensorflow.keras.callbacks import ModelCheckpoint\n",
    "\n",
    "from tqdm import tqdm #progress bar\n",
    "\n",
    "# from spellchecker import SpellChecker"
   ]
  },
  {
   "cell_type": "code",
   "execution_count": 1,
   "id": "97a36d8e-f5a0-4ae1-82a1-30eaa7d0d2a1",
   "metadata": {
    "id": "97a36d8e-f5a0-4ae1-82a1-30eaa7d0d2a1"
   },
   "outputs": [],
   "source": [
    "train_path = 'gs://gbi_ml/classification_hackathon/bbby_train_new.csv'\n",
    "test_path = 'gs://gbi_ml/classification_hackathon/bbby_test_new.csv'\n",
    "# train_path = 'gs://gbi_ml/classification_hackathon/bbby_train_30_tokenization.pkl'\n",
    "# test_path = 'gs://gbi_ml/classification_hackathon/bbby_test_tokenization.pkl'"
   ]
  },
  {
   "cell_type": "code",
   "execution_count": null,
   "id": "UQc5wWoiEzqU",
   "metadata": {
    "id": "UQc5wWoiEzqU"
   },
   "outputs": [],
   "source": [
    "!pip install gcsfs"
   ]
  },
  {
   "cell_type": "code",
   "execution_count": null,
   "id": "8XfMdiO8HCMa",
   "metadata": {
    "id": "8XfMdiO8HCMa"
   },
   "outputs": [],
   "source": [
    "!gcloud auth login"
   ]
  },
  {
   "cell_type": "code",
   "execution_count": 8,
   "id": "NJefLCFnHIzg",
   "metadata": {
    "colab": {
     "base_uri": "https://localhost:8080/"
    },
    "id": "NJefLCFnHIzg",
    "outputId": "bab397f3-e8c1-4a6d-a6eb-856c192558b4"
   },
   "outputs": [
    {
     "name": "stdout",
     "output_type": "stream",
     "text": [
      "Updated property [core/project].\n"
     ]
    }
   ],
   "source": [
    "!gcloud config set project 'groupby-development'"
   ]
  },
  {
   "cell_type": "code",
   "execution_count": 9,
   "id": "rzXgESUDHneg",
   "metadata": {
    "id": "rzXgESUDHneg"
   },
   "outputs": [],
   "source": [
    "from google.colab import auth\n",
    "auth.authenticate_user()"
   ]
  },
  {
   "cell_type": "code",
   "execution_count": 10,
   "id": "55a00bed-2b5e-4a18-8565-42d7c0a8acfa",
   "metadata": {
    "id": "55a00bed-2b5e-4a18-8565-42d7c0a8acfa"
   },
   "outputs": [],
   "source": [
    "df = pd.read_csv(train_path)"
   ]
  },
  {
   "cell_type": "code",
   "execution_count": 2,
   "id": "41016920-88c4-4417-ba5a-dde1477a0bd3",
   "metadata": {
    "id": "41016920-88c4-4417-ba5a-dde1477a0bd3"
   },
   "outputs": [
    {
     "name": "stdout",
     "output_type": "stream",
     "text": [
      "ERROR! Session/line number was not unique in database. History logging moved to new session 278\n"
     ]
    }
   ],
   "source": [
    "test_df = pd.read_csv(test_path)"
   ]
  },
  {
   "cell_type": "code",
   "execution_count": 12,
   "id": "6931dc19-eae1-4be6-9550-e051f070cac9",
   "metadata": {
    "colab": {
     "base_uri": "https://localhost:8080/"
    },
    "id": "6931dc19-eae1-4be6-9550-e051f070cac9",
    "outputId": "0a6e016e-690b-41ab-a103-da074621c539"
   },
   "outputs": [
    {
     "data": {
      "text/plain": [
       "((308284, 12), (19481, 8))"
      ]
     },
     "execution_count": 12,
     "metadata": {},
     "output_type": "execute_result"
    }
   ],
   "source": [
    "df.shape, test_df.shape"
   ]
  },
  {
   "cell_type": "code",
   "execution_count": 21,
   "id": "KihZezl-wqwQ",
   "metadata": {
    "colab": {
     "base_uri": "https://localhost:8080/"
    },
    "id": "KihZezl-wqwQ",
    "outputId": "dcaec15e-e602-443d-a849-994cda1ed7ac"
   },
   "outputs": [
    {
     "data": {
      "text/plain": [
       "Index(['bucket_id', 'external_id', 'customer_id', 'bucket_name', 'product_id',\n",
       "       'product_name', 'description', 'image_url', 'len_desc', 'len_name',\n",
       "       'raw_product_name', 'raw_product_description'],\n",
       "      dtype='object')"
      ]
     },
     "execution_count": 21,
     "metadata": {},
     "output_type": "execute_result"
    }
   ],
   "source": [
    "df.columns"
   ]
  },
  {
   "cell_type": "code",
   "execution_count": 3,
   "id": "b1kPXoRCRLp7",
   "metadata": {
    "id": "b1kPXoRCRLp7"
   },
   "outputs": [
    {
     "name": "stdout",
     "output_type": "stream",
     "text": [
      "ERROR! Session/line number was not unique in database. History logging moved to new session 279\n"
     ]
    }
   ],
   "source": [
    "# cats = sorted(df.bucket_name.unique())\n",
    "# id2label = {id_:name_ for id_, name_ in enumerate(cats)}\n",
    "# label2id = {name_: id_ for id_, name_ in enumerate(cats)}"
   ]
  },
  {
   "cell_type": "code",
   "execution_count": 4,
   "id": "351ce00d-0f02-46b2-a520-c7097ca27854",
   "metadata": {},
   "outputs": [
    {
     "name": "stdout",
     "output_type": "stream",
     "text": [
      "ERROR! Session/line number was not unique in database. History logging moved to new session 280\n"
     ]
    }
   ],
   "source": [
    "import pickle \n",
    "with open('id2label.pickle', 'rb') as handle:\n",
    "    id2label = pickle.load(handle)\n",
    "    \n",
    "with open('label2id.pickle', 'rb') as handle:\n",
    "    label2id = pickle.load(handle)"
   ]
  },
  {
   "cell_type": "code",
   "execution_count": 5,
   "id": "Hbo4TDSqRIdG",
   "metadata": {
    "id": "Hbo4TDSqRIdG"
   },
   "outputs": [],
   "source": [
    "from collections import defaultdict\n",
    "  \n",
    "def def_value():\n",
    "    return -1\n",
    "      \n",
    "# Defining the dict\n",
    "d = defaultdict(int, label2id)"
   ]
  },
  {
   "cell_type": "code",
   "execution_count": 6,
   "id": "OyFoPOecRRLI",
   "metadata": {
    "id": "OyFoPOecRRLI"
   },
   "outputs": [
    {
     "name": "stdout",
     "output_type": "stream",
     "text": [
      "ERROR! Session/line number was not unique in database. History logging moved to new session 281\n"
     ]
    }
   ],
   "source": [
    "# df['label'] = df.bucket_name.apply(lambda x: label2id[x])\n",
    "test_df['label'] = test_df['Manual Classification Bucket'].apply(lambda x: d[x])"
   ]
  },
  {
   "cell_type": "code",
   "execution_count": 15,
   "id": "IQkw0bwivtku",
   "metadata": {
    "id": "IQkw0bwivtku"
   },
   "outputs": [],
   "source": [
    "from tqdm import tqdm\n",
    "import tensorflow as tf\n",
    "import tensorflow_hub as hub\n"
   ]
  },
  {
   "cell_type": "code",
   "execution_count": null,
   "id": "d2b963eb-36c4-4d01-ac5a-064675f826e4",
   "metadata": {
    "id": "bk-GTBAZvcEJ"
   },
   "outputs": [
    {
     "name": "stderr",
     "output_type": "stream",
     "text": [
      "ERROR:root:Internal Python error in the inspect module.\n",
      "Below is the traceback from this internal error.\n",
      "\n",
      "ERROR:root:Internal Python error in the inspect module.\n",
      "Below is the traceback from this internal error.\n",
      "\n",
      "ERROR:root:Internal Python error in the inspect module.\n",
      "Below is the traceback from this internal error.\n",
      "\n"
     ]
    },
    {
     "name": "stdout",
     "output_type": "stream",
     "text": [
      "Traceback (most recent call last):\n",
      "  File \"/opt/conda/lib/python3.7/site-packages/IPython/core/interactiveshell.py\", line 3552, in run_code\n",
      "    exec(code_obj, self.user_global_ns, self.user_ns)\n",
      "  File \"/tmp/ipykernel_24234/3810780756.py\", line 4, in <module>\n",
      "    use = hub.load(\"https://tfhub.dev/google/universal-sentence-encoder-multilingual-large/3\")\n",
      "NameError: name 'hub' is not defined\n",
      "\n",
      "During handling of the above exception, another exception occurred:\n",
      "\n",
      "Traceback (most recent call last):\n",
      "  File \"/opt/conda/lib/python3.7/site-packages/IPython/core/interactiveshell.py\", line 2098, in showtraceback\n",
      "    stb = value._render_traceback_()\n",
      "AttributeError: 'NameError' object has no attribute '_render_traceback_'\n",
      "\n",
      "During handling of the above exception, another exception occurred:\n",
      "\n",
      "Traceback (most recent call last):\n",
      "  File \"/opt/conda/lib/python3.7/site-packages/IPython/core/ultratb.py\", line 1101, in get_records\n",
      "    return _fixed_getinnerframes(etb, number_of_lines_of_context, tb_offset)\n",
      "  File \"/opt/conda/lib/python3.7/site-packages/IPython/core/ultratb.py\", line 248, in wrapped\n",
      "    return f(*args, **kwargs)\n",
      "  File \"/opt/conda/lib/python3.7/site-packages/IPython/core/ultratb.py\", line 281, in _fixed_getinnerframes\n",
      "    records = fix_frame_records_filenames(inspect.getinnerframes(etb, context))\n",
      "  File \"/opt/conda/lib/python3.7/inspect.py\", line 1502, in getinnerframes\n",
      "    frameinfo = (tb.tb_frame,) + getframeinfo(tb, context)\n",
      "  File \"/opt/conda/lib/python3.7/inspect.py\", line 1460, in getframeinfo\n",
      "    filename = getsourcefile(frame) or getfile(frame)\n",
      "  File \"/opt/conda/lib/python3.7/inspect.py\", line 696, in getsourcefile\n",
      "    if getattr(getmodule(object, filename), '__loader__', None) is not None:\n",
      "  File \"/opt/conda/lib/python3.7/inspect.py\", line 733, in getmodule\n",
      "    if ismodule(module) and hasattr(module, '__file__'):\n",
      "  File \"/opt/conda/lib/python3.7/site-packages/tensorflow/__init__.py\", line 50, in __getattr__\n",
      "    module = self._load()\n",
      "  File \"/opt/conda/lib/python3.7/site-packages/tensorflow/__init__.py\", line 44, in _load\n",
      "    module = _importlib.import_module(self.__name__)\n",
      "  File \"/opt/conda/lib/python3.7/importlib/__init__.py\", line 127, in import_module\n",
      "    return _bootstrap._gcd_import(name[level:], package, level)\n",
      "  File \"<frozen importlib._bootstrap>\", line 1006, in _gcd_import\n",
      "  File \"<frozen importlib._bootstrap>\", line 983, in _find_and_load\n",
      "  File \"<frozen importlib._bootstrap>\", line 965, in _find_and_load_unlocked\n",
      "ModuleNotFoundError: No module named 'tensorflow_core.estimator'\n",
      "Traceback (most recent call last):\n",
      "  File \"/opt/conda/lib/python3.7/site-packages/IPython/core/interactiveshell.py\", line 3552, in run_code\n",
      "    exec(code_obj, self.user_global_ns, self.user_ns)\n",
      "  File \"/tmp/ipykernel_24234/3810780756.py\", line 4, in <module>\n",
      "    use = hub.load(\"https://tfhub.dev/google/universal-sentence-encoder-multilingual-large/3\")\n",
      "NameError: name 'hub' is not defined\n",
      "\n",
      "During handling of the above exception, another exception occurred:\n",
      "\n",
      "Traceback (most recent call last):\n",
      "  File \"/opt/conda/lib/python3.7/site-packages/IPython/core/interactiveshell.py\", line 2098, in showtraceback\n",
      "    stb = value._render_traceback_()\n",
      "AttributeError: 'NameError' object has no attribute '_render_traceback_'\n",
      "\n",
      "During handling of the above exception, another exception occurred:\n",
      "\n",
      "Traceback (most recent call last):\n",
      "  File \"/opt/conda/lib/python3.7/site-packages/IPython/core/interactiveshell.py\", line 3472, in run_ast_nodes\n",
      "    if (await self.run_code(code, result,  async_=asy)):\n",
      "  File \"/opt/conda/lib/python3.7/site-packages/IPython/core/interactiveshell.py\", line 3569, in run_code\n",
      "    self.showtraceback(running_compiled_code=True)\n",
      "  File \"/opt/conda/lib/python3.7/site-packages/IPython/core/interactiveshell.py\", line 2101, in showtraceback\n",
      "    value, tb, tb_offset=tb_offset)\n",
      "  File \"/opt/conda/lib/python3.7/site-packages/IPython/core/ultratb.py\", line 1368, in structured_traceback\n",
      "    self, etype, value, tb, tb_offset, number_of_lines_of_context)\n",
      "  File \"/opt/conda/lib/python3.7/site-packages/IPython/core/ultratb.py\", line 1268, in structured_traceback\n",
      "    self, etype, value, tb, tb_offset, number_of_lines_of_context\n",
      "  File \"/opt/conda/lib/python3.7/site-packages/IPython/core/ultratb.py\", line 1125, in structured_traceback\n",
      "    tb_offset)\n",
      "  File \"/opt/conda/lib/python3.7/site-packages/IPython/core/ultratb.py\", line 1082, in format_exception_as_a_whole\n",
      "    last_unique, recursion_repeat = find_recursion(orig_etype, evalue, records)\n",
      "  File \"/opt/conda/lib/python3.7/site-packages/IPython/core/ultratb.py\", line 382, in find_recursion\n",
      "    return len(records), 0\n",
      "TypeError: object of type 'NoneType' has no len()\n",
      "\n",
      "During handling of the above exception, another exception occurred:\n",
      "\n",
      "Traceback (most recent call last):\n",
      "  File \"/opt/conda/lib/python3.7/site-packages/IPython/core/interactiveshell.py\", line 2098, in showtraceback\n",
      "    stb = value._render_traceback_()\n",
      "AttributeError: 'TypeError' object has no attribute '_render_traceback_'\n",
      "\n",
      "During handling of the above exception, another exception occurred:\n",
      "\n",
      "Traceback (most recent call last):\n",
      "  File \"/opt/conda/lib/python3.7/site-packages/IPython/core/ultratb.py\", line 1101, in get_records\n",
      "    return _fixed_getinnerframes(etb, number_of_lines_of_context, tb_offset)\n",
      "  File \"/opt/conda/lib/python3.7/site-packages/IPython/core/ultratb.py\", line 248, in wrapped\n",
      "    return f(*args, **kwargs)\n",
      "  File \"/opt/conda/lib/python3.7/site-packages/IPython/core/ultratb.py\", line 281, in _fixed_getinnerframes\n",
      "    records = fix_frame_records_filenames(inspect.getinnerframes(etb, context))\n",
      "  File \"/opt/conda/lib/python3.7/inspect.py\", line 1502, in getinnerframes\n",
      "    frameinfo = (tb.tb_frame,) + getframeinfo(tb, context)\n",
      "  File \"/opt/conda/lib/python3.7/inspect.py\", line 1460, in getframeinfo\n",
      "    filename = getsourcefile(frame) or getfile(frame)\n",
      "  File \"/opt/conda/lib/python3.7/inspect.py\", line 696, in getsourcefile\n",
      "    if getattr(getmodule(object, filename), '__loader__', None) is not None:\n",
      "  File \"/opt/conda/lib/python3.7/inspect.py\", line 733, in getmodule\n",
      "    if ismodule(module) and hasattr(module, '__file__'):\n",
      "  File \"/opt/conda/lib/python3.7/site-packages/tensorflow/__init__.py\", line 50, in __getattr__\n",
      "    module = self._load()\n",
      "  File \"/opt/conda/lib/python3.7/site-packages/tensorflow/__init__.py\", line 44, in _load\n",
      "    module = _importlib.import_module(self.__name__)\n",
      "  File \"/opt/conda/lib/python3.7/importlib/__init__.py\", line 127, in import_module\n",
      "    return _bootstrap._gcd_import(name[level:], package, level)\n",
      "  File \"<frozen importlib._bootstrap>\", line 1006, in _gcd_import\n",
      "  File \"<frozen importlib._bootstrap>\", line 983, in _find_and_load\n",
      "  File \"<frozen importlib._bootstrap>\", line 965, in _find_and_load_unlocked\n",
      "ModuleNotFoundError: No module named 'tensorflow_core.estimator'\n",
      "Traceback (most recent call last):\n",
      "  File \"/opt/conda/lib/python3.7/site-packages/IPython/core/interactiveshell.py\", line 3552, in run_code\n",
      "    exec(code_obj, self.user_global_ns, self.user_ns)\n",
      "  File \"/tmp/ipykernel_24234/3810780756.py\", line 4, in <module>\n",
      "    use = hub.load(\"https://tfhub.dev/google/universal-sentence-encoder-multilingual-large/3\")\n",
      "NameError: name 'hub' is not defined\n",
      "\n",
      "During handling of the above exception, another exception occurred:\n",
      "\n",
      "Traceback (most recent call last):\n",
      "  File \"/opt/conda/lib/python3.7/site-packages/IPython/core/interactiveshell.py\", line 2098, in showtraceback\n",
      "    stb = value._render_traceback_()\n",
      "AttributeError: 'NameError' object has no attribute '_render_traceback_'\n",
      "\n",
      "During handling of the above exception, another exception occurred:\n",
      "\n",
      "Traceback (most recent call last):\n",
      "  File \"/opt/conda/lib/python3.7/site-packages/IPython/core/interactiveshell.py\", line 3472, in run_ast_nodes\n",
      "    if (await self.run_code(code, result,  async_=asy)):\n",
      "  File \"/opt/conda/lib/python3.7/site-packages/IPython/core/interactiveshell.py\", line 3569, in run_code\n",
      "    self.showtraceback(running_compiled_code=True)\n",
      "  File \"/opt/conda/lib/python3.7/site-packages/IPython/core/interactiveshell.py\", line 2101, in showtraceback\n",
      "    value, tb, tb_offset=tb_offset)\n",
      "  File \"/opt/conda/lib/python3.7/site-packages/IPython/core/ultratb.py\", line 1368, in structured_traceback\n",
      "    self, etype, value, tb, tb_offset, number_of_lines_of_context)\n",
      "  File \"/opt/conda/lib/python3.7/site-packages/IPython/core/ultratb.py\", line 1268, in structured_traceback\n",
      "    self, etype, value, tb, tb_offset, number_of_lines_of_context\n",
      "  File \"/opt/conda/lib/python3.7/site-packages/IPython/core/ultratb.py\", line 1125, in structured_traceback\n",
      "    tb_offset)\n",
      "  File \"/opt/conda/lib/python3.7/site-packages/IPython/core/ultratb.py\", line 1082, in format_exception_as_a_whole\n",
      "    last_unique, recursion_repeat = find_recursion(orig_etype, evalue, records)\n",
      "  File \"/opt/conda/lib/python3.7/site-packages/IPython/core/ultratb.py\", line 382, in find_recursion\n",
      "    return len(records), 0\n",
      "TypeError: object of type 'NoneType' has no len()\n",
      "\n",
      "During handling of the above exception, another exception occurred:\n",
      "\n",
      "Traceback (most recent call last):\n",
      "  File \"/opt/conda/lib/python3.7/site-packages/IPython/core/interactiveshell.py\", line 2098, in showtraceback\n",
      "    stb = value._render_traceback_()\n",
      "AttributeError: 'TypeError' object has no attribute '_render_traceback_'\n",
      "\n",
      "During handling of the above exception, another exception occurred:\n",
      "\n",
      "Traceback (most recent call last):\n",
      "  File \"/opt/conda/lib/python3.7/site-packages/IPython/core/interactiveshell.py\", line 3029, in _run_cell\n",
      "    return runner(coro)\n",
      "  File \"/opt/conda/lib/python3.7/site-packages/IPython/core/async_helpers.py\", line 78, in _pseudo_sync_runner\n",
      "    coro.send(None)\n",
      "  File \"/opt/conda/lib/python3.7/site-packages/IPython/core/interactiveshell.py\", line 3257, in run_cell_async\n",
      "    interactivity=interactivity, compiler=compiler, result=result)\n",
      "  File \"/opt/conda/lib/python3.7/site-packages/IPython/core/interactiveshell.py\", line 3491, in run_ast_nodes\n",
      "    self.showtraceback()\n",
      "  File \"/opt/conda/lib/python3.7/site-packages/IPython/core/interactiveshell.py\", line 2101, in showtraceback\n",
      "    value, tb, tb_offset=tb_offset)\n",
      "  File \"/opt/conda/lib/python3.7/site-packages/IPython/core/ultratb.py\", line 1368, in structured_traceback\n",
      "    self, etype, value, tb, tb_offset, number_of_lines_of_context)\n",
      "  File \"/opt/conda/lib/python3.7/site-packages/IPython/core/ultratb.py\", line 1268, in structured_traceback\n",
      "    self, etype, value, tb, tb_offset, number_of_lines_of_context\n",
      "  File \"/opt/conda/lib/python3.7/site-packages/IPython/core/ultratb.py\", line 1143, in structured_traceback\n",
      "    chained_exceptions_tb_offset)\n",
      "  File \"/opt/conda/lib/python3.7/site-packages/IPython/core/ultratb.py\", line 1082, in format_exception_as_a_whole\n",
      "    last_unique, recursion_repeat = find_recursion(orig_etype, evalue, records)\n",
      "  File \"/opt/conda/lib/python3.7/site-packages/IPython/core/ultratb.py\", line 382, in find_recursion\n",
      "    return len(records), 0\n",
      "TypeError: object of type 'NoneType' has no len()\n",
      "\n",
      "During handling of the above exception, another exception occurred:\n",
      "\n",
      "Traceback (most recent call last):\n",
      "  File \"/opt/conda/lib/python3.7/site-packages/IPython/core/interactiveshell.py\", line 2098, in showtraceback\n",
      "    stb = value._render_traceback_()\n",
      "AttributeError: 'TypeError' object has no attribute '_render_traceback_'\n",
      "\n",
      "During handling of the above exception, another exception occurred:\n",
      "\n",
      "Traceback (most recent call last):\n",
      "  File \"/opt/conda/lib/python3.7/site-packages/IPython/core/ultratb.py\", line 1101, in get_records\n",
      "    return _fixed_getinnerframes(etb, number_of_lines_of_context, tb_offset)\n",
      "  File \"/opt/conda/lib/python3.7/site-packages/IPython/core/ultratb.py\", line 248, in wrapped\n",
      "    return f(*args, **kwargs)\n",
      "  File \"/opt/conda/lib/python3.7/site-packages/IPython/core/ultratb.py\", line 281, in _fixed_getinnerframes\n",
      "    records = fix_frame_records_filenames(inspect.getinnerframes(etb, context))\n",
      "  File \"/opt/conda/lib/python3.7/inspect.py\", line 1502, in getinnerframes\n",
      "    frameinfo = (tb.tb_frame,) + getframeinfo(tb, context)\n",
      "  File \"/opt/conda/lib/python3.7/inspect.py\", line 1460, in getframeinfo\n",
      "    filename = getsourcefile(frame) or getfile(frame)\n",
      "  File \"/opt/conda/lib/python3.7/inspect.py\", line 696, in getsourcefile\n",
      "    if getattr(getmodule(object, filename), '__loader__', None) is not None:\n",
      "  File \"/opt/conda/lib/python3.7/inspect.py\", line 733, in getmodule\n",
      "    if ismodule(module) and hasattr(module, '__file__'):\n",
      "  File \"/opt/conda/lib/python3.7/site-packages/tensorflow/__init__.py\", line 50, in __getattr__\n",
      "    module = self._load()\n",
      "  File \"/opt/conda/lib/python3.7/site-packages/tensorflow/__init__.py\", line 44, in _load\n",
      "    module = _importlib.import_module(self.__name__)\n",
      "  File \"/opt/conda/lib/python3.7/importlib/__init__.py\", line 127, in import_module\n",
      "    return _bootstrap._gcd_import(name[level:], package, level)\n",
      "  File \"<frozen importlib._bootstrap>\", line 1006, in _gcd_import\n",
      "  File \"<frozen importlib._bootstrap>\", line 983, in _find_and_load\n",
      "  File \"<frozen importlib._bootstrap>\", line 965, in _find_and_load_unlocked\n",
      "ModuleNotFoundError: No module named 'tensorflow_core.estimator'\n"
     ]
    }
   ],
   "source": [
    "# SENTENCES EMBEDDING\n",
    "\n",
    "# Load encoder from Tensorflow for LGBM model\n",
    "use = hub.load(\"https://tfhub.dev/google/universal-sentence-encoder-multilingual-large/3\")"
   ]
  },
  {
   "cell_type": "code",
   "execution_count": null,
   "id": "12ff2ced-c5b0-4c39-a6e1-5c452f7da0e7",
   "metadata": {
    "id": "bk-GTBAZvcEJ"
   },
   "outputs": [],
   "source": [
    "# Embed sentences for the training set\n",
    "X_train = []\n",
    "for r in tqdm(df.raw_product_description.values):\n",
    "  emb = use(r)\n",
    "  review_emb = tf.reshape(emb, [-1]).numpy()\n",
    "  X_train.append(review_emb)\n",
    "\n",
    "X_train = np.array(X_train)"
   ]
  },
  {
   "cell_type": "code",
   "execution_count": 26,
   "id": "9Zme0CHhQ7Pg",
   "metadata": {
    "colab": {
     "base_uri": "https://localhost:8080/"
    },
    "id": "9Zme0CHhQ7Pg",
    "outputId": "ce56beac-84bd-4848-a7a7-03f971f5dc1d"
   },
   "outputs": [
    {
     "name": "stderr",
     "output_type": "stream",
     "text": [
      "100%|██████████| 19481/19481 [08:23<00:00, 38.72it/s]\n"
     ]
    }
   ],
   "source": [
    "y_train = df.label.values\n",
    "\n",
    "# Embed sentences for the validation set\n",
    "Val_test = []\n",
    "for r in tqdm(test_df.raw_product_description.values):\n",
    "    emb = use(r)\n",
    "    review_emb = tf.reshape(emb, [-1]).numpy()\n",
    "    Val_test.append(review_emb)"
   ]
  },
  {
   "cell_type": "code",
   "execution_count": 27,
   "id": "PTlxRQfbx7ZD",
   "metadata": {
    "id": "PTlxRQfbx7ZD"
   },
   "outputs": [],
   "source": [
    "import gcsfs\n",
    "import pickle \n",
    "\n",
    "base_dir = 'gbi_ml/classification_hackathon/'\n",
    "fs = gcsfs.GCSFileSystem()\n",
    "\n",
    "with fs.open(base_dir+'X_train.pickle', 'wb') as handle:\n",
    "    pickle.dump(X_train, handle, protocol=pickle.HIGHEST_PROTOCOL)\n",
    "\n",
    "with fs.open(base_dir+'X_test.pickle', 'wb') as handle:\n",
    "    pickle.dump(Val_test, handle, protocol=pickle.HIGHEST_PROTOCOL)"
   ]
  },
  {
   "cell_type": "code",
   "execution_count": 29,
   "id": "5cj6ZkPFTLAu",
   "metadata": {
    "colab": {
     "base_uri": "https://localhost:8080/"
    },
    "id": "5cj6ZkPFTLAu",
    "outputId": "a36e123f-3b26-4b9a-e9f3-d2faec0bd792"
   },
   "outputs": [
    {
     "name": "stdout",
     "output_type": "stream",
     "text": [
      "Looking in indexes: https://pypi.org/simple, https://us-python.pkg.dev/colab-wheels/public/simple/\n",
      "Requirement already satisfied: lightgbm in /usr/local/lib/python3.9/dist-packages (3.3.5)\n",
      "Requirement already satisfied: numpy in /usr/local/lib/python3.9/dist-packages (from lightgbm) (1.22.4)\n",
      "Requirement already satisfied: wheel in /usr/local/lib/python3.9/dist-packages (from lightgbm) (0.40.0)\n",
      "Requirement already satisfied: scikit-learn!=0.22.0 in /usr/local/lib/python3.9/dist-packages (from lightgbm) (1.2.2)\n",
      "Requirement already satisfied: scipy in /usr/local/lib/python3.9/dist-packages (from lightgbm) (1.10.1)\n",
      "Requirement already satisfied: threadpoolctl>=2.0.0 in /usr/local/lib/python3.9/dist-packages (from scikit-learn!=0.22.0->lightgbm) (3.1.0)\n",
      "Requirement already satisfied: joblib>=1.1.1 in /usr/local/lib/python3.9/dist-packages (from scikit-learn!=0.22.0->lightgbm) (1.1.1)\n"
     ]
    }
   ],
   "source": [
    "!pip install lightgbm"
   ]
  },
  {
   "cell_type": "code",
   "execution_count": 30,
   "id": "wPTIYqAaTaEw",
   "metadata": {
    "id": "wPTIYqAaTaEw"
   },
   "outputs": [],
   "source": [
    "import lightgbm as lgbm"
   ]
  },
  {
   "cell_type": "code",
   "execution_count": 43,
   "id": "zMY9X_U_wHLR",
   "metadata": {
    "id": "zMY9X_U_wHLR"
   },
   "outputs": [],
   "source": [
    "# LGBM\n",
    "\n",
    "# Split data into train and testing data\n",
    "X_train, X_test, y_train, y_test = train_test_split(X_train, y_train, test_size=0.1, random_state = 42, stratify=y_train)\n",
    "\n",
    "# Get the train and test data for the training sequence\n",
    "train_data = lgbm.Dataset(X_train, label=y_train)\n",
    "test_data = lgbm.Dataset(X_test, label=y_test)"
   ]
  },
  {
   "cell_type": "code",
   "execution_count": 45,
   "id": "7i9QuU9sWk0O",
   "metadata": {
    "colab": {
     "base_uri": "https://localhost:8080/"
    },
    "id": "7i9QuU9sWk0O",
    "outputId": "47052827-13b6-46aa-993c-42127db2b705"
   },
   "outputs": [
    {
     "data": {
      "text/plain": [
       "array([601, 447, 394, 303, 665])"
      ]
     },
     "execution_count": 45,
     "metadata": {},
     "output_type": "execute_result"
    }
   ],
   "source": [
    "y_test[:5]"
   ]
  },
  {
   "cell_type": "code",
   "execution_count": 1,
   "id": "7seiu9bhSK_V",
   "metadata": {
    "colab": {
     "base_uri": "https://localhost:8080/",
     "height": 235
    },
    "id": "7seiu9bhSK_V",
    "outputId": "6bd33c46-e9f1-4926-d56e-6e9cfdfc2713"
   },
   "outputs": [
    {
     "ename": "NameError",
     "evalue": "ignored",
     "output_type": "error",
     "traceback": [
      "\u001b[0;31m---------------------------------------------------------------------------\u001b[0m",
      "\u001b[0;31mNameError\u001b[0m                                 Traceback (most recent call last)",
      "\u001b[0;32m<ipython-input-1-35e617560ee6>\u001b[0m in \u001b[0;36m<module>\u001b[0;34m\u001b[0m\n\u001b[1;32m     13\u001b[0m     \u001b[0;31m# 'max_depth': 10,\u001b[0m\u001b[0;34m\u001b[0m\u001b[0;34m\u001b[0m\u001b[0m\n\u001b[1;32m     14\u001b[0m     \u001b[0;31m# 'device': 'gpu',\u001b[0m\u001b[0;34m\u001b[0m\u001b[0;34m\u001b[0m\u001b[0m\n\u001b[0;32m---> 15\u001b[0;31m     \u001b[0;34m'num_classes'\u001b[0m\u001b[0;34m:\u001b[0m \u001b[0mlen\u001b[0m\u001b[0;34m(\u001b[0m\u001b[0mid2label\u001b[0m\u001b[0;34m)\u001b[0m\u001b[0;34m,\u001b[0m\u001b[0;34m\u001b[0m\u001b[0;34m\u001b[0m\u001b[0m\n\u001b[0m\u001b[1;32m     16\u001b[0m     \u001b[0;34m'min_data_in_leaf'\u001b[0m\u001b[0;34m:\u001b[0m\u001b[0;36m300\u001b[0m\u001b[0;34m\u001b[0m\u001b[0;34m\u001b[0m\u001b[0m\n\u001b[1;32m     17\u001b[0m }\n",
      "\u001b[0;31mNameError\u001b[0m: name 'id2label' is not defined"
     ]
    }
   ],
   "source": [
    "# Parameters we'll use for the prediction\n",
    "parameters = {\n",
    "    # 'application': 'binary',\n",
    "    'objective': 'multiclass',\n",
    "    'metric': 'multi_logloss',\n",
    "    'boosting': 'gbdt',\n",
    "    # 'num_leaves': 31,\n",
    "    # 'feature_fraction': 0.5,\n",
    "    # 'bagging_fraction': 0.5,\n",
    "    # 'bagging_freq': 20,\n",
    "    # 'learning_rate': 0.05,\n",
    "    # 'verbose': 0,\n",
    "    # 'max_depth': 10,\n",
    "    # 'device': 'gpu',\n",
    "    'num_classes': len(id2label),\n",
    "    'min_data_in_leaf':300\n",
    "}\n",
    "\n",
    "# Train the classifier\n",
    "# model = lgbm.LGBMClassifier()\n",
    "# model = lgbm.LGBMClassifier(boosting_type='gbdt', num_leaves=31, max_depth=- 1, learning_rate=0.1, n_estimators=300, device = \"gpu\")\n",
    "classifier = lgbm.train(parameters,\n",
    "                       train_data,\n",
    "                       valid_sets=[train_data, test_data],\n",
    "                      #  num_boost_round=5000,\n",
    "                       early_stopping_rounds=10)\n",
    "\n",
    "\n",
    "# PREDICTION\n",
    "val_pred = classifier.predict(Val_test)\n",
    "\n",
    "# # Submission file\n",
    "# submission_df['target'] = val_pred.round().astype(int)\n",
    "# submission_df.to_csv('submission_lgbm.csv', index=False)"
   ]
  },
  {
   "cell_type": "code",
   "execution_count": null,
   "id": "M-OTHi43WTn2",
   "metadata": {
    "id": "M-OTHi43WTn2"
   },
   "outputs": [],
   "source": []
  }
 ],
 "metadata": {
  "accelerator": "GPU",
  "colab": {
   "include_colab_link": true,
   "provenance": []
  },
  "environment": {
   "kernel": "python3",
   "name": "tf-gpu.1-15.m93",
   "type": "gcloud",
   "uri": "gcr.io/deeplearning-platform-release/tf-gpu.1-15:m93"
  },
  "gpuClass": "standard",
  "kernelspec": {
   "display_name": "Python 3",
   "language": "python",
   "name": "python3"
  },
  "language_info": {
   "codemirror_mode": {
    "name": "ipython",
    "version": 3
   },
   "file_extension": ".py",
   "mimetype": "text/x-python",
   "name": "python",
   "nbconvert_exporter": "python",
   "pygments_lexer": "ipython3",
   "version": "3.7.12"
  }
 },
 "nbformat": 4,
 "nbformat_minor": 5
}
